2023-12-23 12:28:13 DEBUG:__main__	Command line: run_BUSCO.py
2023-12-23 12:28:13 INFO:__main__	***** Start a BUSCO v5.5.0 analysis, current time: 12/23/2023 12:28:13 *****
2023-12-23 12:28:13 DEBUG:busco.ConfigManager	Getting config file
2023-12-23 12:28:13 INFO:busco.ConfigManager	Configuring BUSCO with local environment
2023-12-23 12:28:13 WARNING:busco.BuscoConfig	Running Auto Lineage Selector as no lineage dataset was specified. This will take a little longer than normal. If you know what lineage dataset you want to use, please specify this in the config file or using the -l (--lineage-dataset) flag in the command line.
2023-12-23 12:28:13 ERROR:busco.BuscoRunner	The parameter "in (--in)" was not provided. Please add it in the config file or provide it through the command line
2023-12-23 12:28:13 DEBUG:busco.BuscoRunner	The parameter "in (--in)" was not provided. Please add it in the config file or provide it through the command line
Traceback (most recent call last):
  File "/usr/lib/python3.8/configparser.py", line 789, in get
    value = d[option]
  File "/usr/lib/python3.8/collections/__init__.py", line 898, in __getitem__
    return self.__missing__(key)            # support subclasses that define __missing__
  File "/usr/lib/python3.8/collections/__init__.py", line 890, in __missing__
    raise KeyError(key)
KeyError: 'in'

During handling of the above exception, another exception occurred:

Traceback (most recent call last):
  File "/home/aboylan/.local/lib/python3.8/site-packages/busco/BuscoConfig.py", line 633, in _check_mandatory_keys_exist
    value = self.get("busco_run", param)
  File "/usr/lib/python3.8/configparser.py", line 792, in get
    raise NoOptionError(option, section)
configparser.NoOptionError: No option 'in' in section: 'busco_run'

During handling of the above exception, another exception occurred:

Traceback (most recent call last):
  File "run_BUSCO.py", line 70, in run
    self.load_config()
  File "run_BUSCO.py", line 62, in load_config
    self.config_manager.load_busco_config_main()
  File "/home/aboylan/.local/lib/python3.8/site-packages/busco/BuscoLogger.py", line 62, in wrapped_func
    self.retval = func(*args, **kwargs)
  File "/home/aboylan/.local/lib/python3.8/site-packages/busco/ConfigManager.py", line 56, in load_busco_config_main
    self.config_main.validate()
  File "/home/aboylan/.local/lib/python3.8/site-packages/busco/BuscoConfig.py", line 542, in validate
    self._check_mandatory_keys_exist()
  File "/home/aboylan/.local/lib/python3.8/site-packages/busco/BuscoLogger.py", line 58, in wrapped_func
    self.retval = func(*args, **kwargs)
  File "/home/aboylan/.local/lib/python3.8/site-packages/busco/BuscoConfig.py", line 694, in _check_mandatory_keys_exist
    raise BatchFatalError(
busco.Exceptions.BatchFatalError: The parameter "in (--in)" was not provided. Please add it in the config file or provide it through the command line
2023-12-23 12:28:13 ERROR:busco.BuscoRunner	BUSCO analysis failed!
2023-12-23 12:28:13 ERROR:busco.BuscoRunner	Check the logs, read the user guide (https://busco.ezlab.org/busco_userguide.html), and check the BUSCO issue board on https://gitlab.com/ezlab/busco/issues

